2024-02-14 17:29:21,895 - login.views - ERROR - An error occurred in file D:\Documents\Coding\Python\VetCalendar\backend\login\views.py on line 236 in user_login(): login(request, user)
2024-02-14 17:32:33,920 - login.views - ERROR - An error occurred in file D:\Documents\Coding\Python\VetCalendar\backend\login\views.py on line 329 in create_user(): data = list(data[0].values())[0]
2024-02-14 18:13:36,346 - login.views - ERROR - An error occurred in file D:\Documents\Coding\Python\VetCalendar\backend\login\views.py on line 329 in create_user(): data = list(data[0].values())[0]
2024-02-14 18:14:40,927 - login.views - ERROR - An error occurred in file D:\Documents\Coding\Python\VetCalendar\backend\login\views.py on line 976 in update_address_city_model(): except User.user_address.RelatedObjectDoesNotExist:
2024-02-16 14:30:56,503 - login.views - ERROR - An error occurred in file D:\Documents\Coding\Python\VetCalendar\backend\login\views.py on line 418 in create_user_new(): data = list(data[0].values())[0]
2024-02-16 14:31:28,096 - login.views - ERROR - An error occurred in file D:\Documents\Coding\Python\VetCalendar\backend\login\views.py on line 426 in create_user_new(): initials = get_unique_initials(data['first_name'], data['middle_name'], data['last_name']),
2024-02-16 14:34:26,523 - login.views - ERROR - An error occurred in file D:\Documents\Coding\Python\VetCalendar\backend\login\views.py on line 434 in create_user_new(): 'nickname': data['nickname'],
2024-02-17 14:30:03,146 - login.views - ERROR - An error occurred in file D:\Documents\Coding\Python\VetCalendar\backend\login\views.py on line 420 in create_user_new(): if not User.objects.filter(email__icontains=data['email']):
2024-02-17 14:34:28,240 - login.views - ERROR - An error occurred in file D:\Documents\Coding\Python\VetCalendar\backend\login\views.py on line 420 in create_user_new(): if not User.objects.filter(email__icontains=data['email']):
2024-02-17 15:15:29,682 - login.views - ERROR - An error occurred in file D:\Documents\Coding\Python\VetCalendar\backend\login\views.py on line 424 in create_user_new(): if not data['middle_name']:
2024-02-17 15:16:35,758 - login.views - ERROR - An error occurred in file D:\Documents\Coding\Python\VetCalendar\backend\login\views.py on line 420 in create_user_new(): if not data['middle_name']:
2024-02-19 10:17:54,129 - login.views - ERROR - An error occurred in file D:\Documents\Coding\Python\VetCalendar\backend\login\views.py on line 1029 in update_address_city_model(): except User.user_address.RelatedObjectDoesNotExist:
2024-02-19 16:31:03,888 - backend.utils - ERROR - An error occurred in file D:\Documents\Coding\Python\VetCalendar\backend\backend\utils.py on line 123 in build_form(): form = FormBuilderNew.objects.values().get(form_name=form)
2024-02-19 16:32:39,905 - backend.utils - ERROR - An error occurred in file D:\Documents\Coding\Python\VetCalendar\backend\backend\utils.py on line 108 in process_forms_test(): if content['save'] == True:
2024-02-19 16:32:44,450 - backend.utils - ERROR - An error occurred in file D:\Documents\Coding\Python\VetCalendar\backend\backend\utils.py on line 108 in process_forms_test(): if content['save'] == True:
2024-02-19 16:41:35,353 - backend.utils - ERROR - An error occurred in file D:\Documents\Coding\Python\VetCalendar\backend\backend\utils.py on line 123 in build_form(): form = FormBuilderNew.objects.values().get(form_name=form)
2024-02-19 16:57:00,994 - backend.utils - ERROR - An error occurred in file D:\Documents\Coding\Python\VetCalendar\backend\backend\utils.py on line 108 in process_forms_test(): if content['save'] == True:
2024-02-19 16:57:34,558 - backend.utils - ERROR - An error occurred in file D:\Documents\Coding\Python\VetCalendar\backend\backend\utils.py on line 109 in process_forms_test(): if content['save'] == True:
2024-02-19 16:59:23,511 - backend.utils - ERROR - An error occurred in file D:\Documents\Coding\Python\VetCalendar\backend\backend\utils.py on line 109 in process_forms_test(): if content['save'] == True:
2024-02-19 16:59:48,678 - backend.utils - ERROR - An error occurred in file D:\Documents\Coding\Python\VetCalendar\backend\backend\utils.py on line 109 in process_forms_test(): if content['save'] == True:
2024-02-19 17:02:25,707 - backend.utils - ERROR - An error occurred in file D:\Documents\Coding\Python\VetCalendar\backend\backend\utils.py on line 172 in save_form(): function = globals()[form['function']]
2024-02-19 17:02:49,801 - backend.utils - ERROR - An error occurred in file D:\Documents\Coding\Python\VetCalendar\backend\backend\utils.py on line 172 in save_form(): function = globals()[form['function']]
2024-02-19 17:07:57,038 - backend.utils - ERROR - An error occurred in file D:\Documents\Coding\Python\VetCalendar\backend\backend\utils.py on line 178 in save_form(): save_function = get_function(form['model']['app'], form['function'])
2024-02-19 17:09:33,364 - backend.utils - ERROR - An error occurred in file D:\Documents\Coding\Python\VetCalendar\backend\backend\utils.py on line 180 in save_form(): save_function = get_function(form['model']['app'], form['function'])
2024-02-19 17:11:50,844 - backend.utils - ERROR - An error occurred in file D:\Documents\Coding\Python\VetCalendar\backend\VetCalendar\views.py on line 1154 in add_event(): latest_date = earliest_date + datetime.timedelta(days=1)
2024-02-19 17:12:55,432 - backend.utils - ERROR - An error occurred in file D:\Documents\Coding\Python\VetCalendar\backend\VetCalendar\views.py on line 1171 in add_event(): shift = creat_update_shift(item)
2024-02-19 17:23:38,066 - backend.utils - ERROR - An error occurred in file D:\Documents\Coding\Python\VetCalendar\backend\backend\utils.py on line 178 in save_form(): print(form['function'])
2024-02-19 17:25:52,655 - backend.utils - ERROR - An error occurred in file D:\Documents\Coding\Python\VetCalendar\backend\backend\utils.py on line 179 in save_form(): print(form['function'])
2024-02-19 17:26:59,351 - backend.utils - ERROR - An error occurred in file D:\Documents\Coding\Python\VetCalendar\backend\backend\utils.py on line 180 in save_form(): print(form['function'])
2024-02-19 17:27:27,529 - backend.utils - ERROR - An error occurred in file D:\Documents\Coding\Python\VetCalendar\backend\backend\utils.py on line 180 in save_form(): print(form['function'])
2024-02-19 17:29:01,515 - login.views - ERROR - An error occurred in file D:\Documents\Coding\Python\VetCalendar\backend\login\views.py on line 618 in account_request(): data = list(data[0].values())[0]
2024-02-19 17:29:44,498 - login.views - ERROR - An error occurred in file D:\Documents\Coding\Python\VetCalendar\backend\login\views.py on line 616 in account_request(): if request.method == 'POST':
2024-02-19 17:31:37,429 - login.views - ERROR - An error occurred in file D:\Documents\Coding\Python\VetCalendar\backend\login\views.py on line 616 in account_request(): print(content['email'])
2024-02-19 17:32:10,006 - login.views - ERROR - An error occurred in file D:\Documents\Coding\Python\VetCalendar\backend\login\views.py on line 616 in account_request(): print(content.email)
2024-02-19 17:32:41,186 - login.views - ERROR - An error occurred in file D:\Documents\Coding\Python\VetCalendar\backend\login\views.py on line 616 in account_request(): print(content['fields']['email'])
2024-02-19 17:37:36,324 - login.views - ERROR - An error occurred in file D:\Documents\Coding\Python\VetCalendar\backend\login\views.py on line 607 in request_access(): return account_request(content['forms'][0])
2024-02-19 17:37:58,729 - login.views - ERROR - An error occurred in file D:\Documents\Coding\Python\VetCalendar\backend\login\views.py on line 607 in request_access(): return account_request(content['forms'][0])
2024-02-19 18:15:42,916 - backend.utils - ERROR - An error occurred in file D:\Documents\Coding\Python\VetCalendar\backend\VetCalendar\views.py on line 908 in get_formbuilder_form(): print(form['function'])
2024-02-19 18:16:58,409 - backend.utils - ERROR - An error occurred in file D:\Documents\Coding\Python\VetCalendar\backend\backend\utils.py on line 127 in build_form(): if content['forms'] != None:
2024-02-19 19:14:46,287 - backend.utils - ERROR - An error occurred in file D:\Documents\Coding\Python\VetCalendar\backend\VetCalendar\views.py on line 973 in handle_forms(): content = json.loads(request.body)
2024-02-19 19:22:12,244 - backend.utils - ERROR - An error occurred in file D:\Documents\Coding\Python\VetCalendar\backend\VetCalendar\views.py on line 973 in handle_forms(): content = json.loads(request.body)
2024-02-19 19:23:14,395 - backend.utils - ERROR - An error occurred in file D:\Documents\Coding\Python\VetCalendar\backend\VetCalendar\views.py on line 973 in handle_forms(): content = json.loads(request.body)
2024-02-19 19:25:52,257 - backend.utils - ERROR - An error occurred in file D:\Documents\Coding\Python\VetCalendar\backend\VetCalendar\views.py on line 973 in handle_forms(): content = json.loads(request.body)
2024-02-19 19:26:12,814 - backend.utils - ERROR - An error occurred in file D:\Documents\Coding\Python\VetCalendar\backend\VetCalendar\views.py on line 973 in handle_forms(): content = json.loads(request.body)
2024-02-19 19:28:05,501 - backend.utils - ERROR - An error occurred in file D:\Documents\Coding\Python\VetCalendar\backend\backend\utils.py on line 131 in build_form(): form = FormBuilderNew.objects.values().get(form_name=form)
2024-02-19 19:42:57,139 - backend.utils - ERROR - An error occurred in file D:\Documents\Coding\Python\VetCalendar\backend\backend\utils.py on line 131 in build_form(): form = FormBuilderNew.objects.values().get(form_name=form)
2024-02-19 20:53:24,800 - backend.utils - ERROR - An error occurred in file D:\Documents\Coding\Python\VetCalendar\backend\backend\utils.py on line 131 in build_form(): form = FormBuilderNew.objects.values().get(form_name=form)
2024-02-19 22:23:00,913 - backend.utils - ERROR - An error occurred in file D:\Documents\Coding\Python\VetCalendar\backend\backend\utils.py on line 141 in build_form(): values = get_model_instance(form['app'], form['model'], content["id"])
2024-02-19 22:54:18,790 - backend.utils - ERROR - An error occurred in file D:\Documents\Coding\Python\VetCalendar\backend\backend\utils.py on line 186 in save_form(): save_function = get_function(form['model']['app'], form['function'])
2024-02-19 22:59:12,755 - backend.utils - ERROR - An error occurred in file D:\Documents\Coding\Python\VetCalendar\backend\backend\utils.py on line 191 in save_form(): save_function = get_function(form['model']['app'], form['function'])
2024-02-19 23:00:15,645 - backend.utils - ERROR - An error occurred in file D:\Documents\Coding\Python\VetCalendar\backend\backend\utils.py on line 195 in save_form(): save_model(form['model'], form_values)
2024-02-19 23:01:18,003 - backend.utils - ERROR - An error occurred in file D:\Documents\Coding\Python\VetCalendar\backend\backend\utils.py on line 191 in save_form(): save_function = get_function(form['model']['app'], form['function'])
2024-02-19 23:07:27,951 - backend.utils - ERROR - An error occurred in file D:\Documents\Coding\Python\VetCalendar\backend\backend\utils.py on line 191 in save_form(): save_function = get_function(form['model']['app'], form['function'])
2024-02-19 23:09:46,174 - backend.utils - ERROR - An error occurred in file D:\Documents\Coding\Python\VetCalendar\backend\backend\utils.py on line 191 in save_form(): save_function = get_function(form['model']['app'], form['function'])
2024-02-19 23:11:24,573 - backend.utils - ERROR - An error occurred in file D:\Documents\Coding\Python\VetCalendar\backend\backend\utils.py on line 191 in save_form(): save_function = get_function(form['model']['app'], form['function'])
2024-02-19 23:13:30,594 - backend.utils - ERROR - An error occurred in file D:\Documents\Coding\Python\VetCalendar\backend\backend\utils.py on line 102 in save_model(): instance.save()
2024-02-19 23:13:30,632 - backend.utils - ERROR - An error occurred in file D:\Documents\Coding\Python\VetCalendar\backend\backend\utils.py on line 202 in save_form(): save_function = get_function(form['model']['app'], form['function'])
2024-02-19 23:13:39,137 - backend.utils - ERROR - An error occurred in file D:\Documents\Coding\Python\VetCalendar\backend\backend\utils.py on line 102 in save_model(): instance.save()
2024-02-19 23:13:39,169 - backend.utils - ERROR - An error occurred in file D:\Documents\Coding\Python\VetCalendar\backend\backend\utils.py on line 202 in save_form(): save_function = get_function(form['model']['app'], form['function'])
2024-02-19 23:14:02,247 - backend.utils - ERROR - An error occurred in file D:\Documents\Coding\Python\VetCalendar\backend\backend\utils.py on line 102 in save_model(): instance.save()
2024-02-19 23:14:02,287 - backend.utils - ERROR - An error occurred in file D:\Documents\Coding\Python\VetCalendar\backend\backend\utils.py on line 96 in save_model(): instance = Model.objects.get(id=id)
2024-02-19 23:14:02,313 - backend.utils - ERROR - An error occurred in file D:\Documents\Coding\Python\VetCalendar\backend\backend\utils.py on line 102 in save_model(): instance.save()
2024-02-19 23:14:02,345 - backend.utils - ERROR - An error occurred in file D:\Documents\Coding\Python\VetCalendar\backend\backend\utils.py on line 202 in save_form(): save_function = get_function(form['model']['app'], form['function'])
2024-02-19 23:14:30,659 - backend.utils - ERROR - An error occurred in file D:\Documents\Coding\Python\VetCalendar\backend\backend\utils.py on line 102 in save_model(): instance.save()
2024-02-19 23:14:30,691 - backend.utils - ERROR - An error occurred in file D:\Documents\Coding\Python\VetCalendar\backend\backend\utils.py on line 96 in save_model(): instance = Model.objects.get(id=id)
2024-02-19 23:14:30,716 - backend.utils - ERROR - An error occurred in file D:\Documents\Coding\Python\VetCalendar\backend\backend\utils.py on line 102 in save_model(): instance.save()
2024-02-19 23:14:30,747 - backend.utils - ERROR - An error occurred in file D:\Documents\Coding\Python\VetCalendar\backend\backend\utils.py on line 96 in save_model(): instance = Model.objects.get(id=id)
2024-02-19 23:14:30,771 - backend.utils - ERROR - An error occurred in file D:\Documents\Coding\Python\VetCalendar\backend\backend\utils.py on line 102 in save_model(): instance.save()
2024-02-19 23:14:30,804 - backend.utils - ERROR - An error occurred in file D:\Documents\Coding\Python\VetCalendar\backend\backend\utils.py on line 96 in save_model(): instance = Model.objects.get(id=id)
2024-02-19 23:14:38,116 - backend.utils - ERROR - An error occurred in file D:\Documents\Coding\Python\VetCalendar\backend\backend\utils.py on line 102 in save_model(): instance.save()
2024-02-19 23:14:38,148 - backend.utils - ERROR - An error occurred in file D:\Documents\Coding\Python\VetCalendar\backend\backend\utils.py on line 96 in save_model(): instance = Model.objects.get(id=id)
2024-02-19 23:14:38,171 - backend.utils - ERROR - An error occurred in file D:\Documents\Coding\Python\VetCalendar\backend\backend\utils.py on line 102 in save_model(): instance.save()
2024-02-19 23:14:38,202 - backend.utils - ERROR - An error occurred in file D:\Documents\Coding\Python\VetCalendar\backend\backend\utils.py on line 96 in save_model(): instance = Model.objects.get(id=id)
2024-02-19 23:14:38,226 - backend.utils - ERROR - An error occurred in file D:\Documents\Coding\Python\VetCalendar\backend\backend\utils.py on line 102 in save_model(): instance.save()
2024-02-19 23:14:38,259 - backend.utils - ERROR - An error occurred in file D:\Documents\Coding\Python\VetCalendar\backend\backend\utils.py on line 96 in save_model(): instance = Model.objects.get(id=id)
2024-02-19 23:14:50,967 - backend.utils - ERROR - An error occurred in file D:\Documents\Coding\Python\VetCalendar\backend\backend\utils.py on line 102 in save_model(): instance.save()
2024-02-19 23:14:50,999 - backend.utils - ERROR - An error occurred in file D:\Documents\Coding\Python\VetCalendar\backend\backend\utils.py on line 96 in save_model(): instance = Model.objects.get(id=id)
2024-02-19 23:14:51,024 - backend.utils - ERROR - An error occurred in file D:\Documents\Coding\Python\VetCalendar\backend\backend\utils.py on line 102 in save_model(): instance.save()
2024-02-19 23:14:51,057 - backend.utils - ERROR - An error occurred in file D:\Documents\Coding\Python\VetCalendar\backend\backend\utils.py on line 96 in save_model(): instance = Model.objects.get(id=id)
2024-02-19 23:14:51,084 - backend.utils - ERROR - An error occurred in file D:\Documents\Coding\Python\VetCalendar\backend\backend\utils.py on line 102 in save_model(): instance.save()
2024-02-19 23:14:51,116 - backend.utils - ERROR - An error occurred in file D:\Documents\Coding\Python\VetCalendar\backend\backend\utils.py on line 96 in save_model(): instance = Model.objects.get(id=id)
2024-02-19 23:15:23,219 - backend.utils - ERROR - An error occurred in file D:\Documents\Coding\Python\VetCalendar\backend\backend\utils.py on line 104 in save_model(): instance.save()
2024-02-19 23:15:23,257 - backend.utils - ERROR - An error occurred in file D:\Documents\Coding\Python\VetCalendar\backend\backend\utils.py on line 96 in save_model(): instance = Model.objects.get(id=id)
2024-02-19 23:15:23,282 - backend.utils - ERROR - An error occurred in file D:\Documents\Coding\Python\VetCalendar\backend\backend\utils.py on line 104 in save_model(): instance.save()
2024-02-19 23:15:23,313 - backend.utils - ERROR - An error occurred in file D:\Documents\Coding\Python\VetCalendar\backend\backend\utils.py on line 96 in save_model(): instance = Model.objects.get(id=id)
2024-02-19 23:15:23,339 - backend.utils - ERROR - An error occurred in file D:\Documents\Coding\Python\VetCalendar\backend\backend\utils.py on line 104 in save_model(): instance.save()
2024-02-19 23:15:23,370 - backend.utils - ERROR - An error occurred in file D:\Documents\Coding\Python\VetCalendar\backend\backend\utils.py on line 96 in save_model(): instance = Model.objects.get(id=id)
2024-02-19 23:15:40,444 - backend.utils - ERROR - An error occurred in file D:\Documents\Coding\Python\VetCalendar\backend\backend\utils.py on line 104 in save_model(): instance.save()
2024-02-19 23:15:40,475 - backend.utils - ERROR - An error occurred in file D:\Documents\Coding\Python\VetCalendar\backend\backend\utils.py on line 96 in save_model(): instance = Model.objects.get(id=id)
2024-02-19 23:15:40,498 - backend.utils - ERROR - An error occurred in file D:\Documents\Coding\Python\VetCalendar\backend\backend\utils.py on line 104 in save_model(): instance.save()
2024-02-19 23:15:40,530 - backend.utils - ERROR - An error occurred in file D:\Documents\Coding\Python\VetCalendar\backend\backend\utils.py on line 96 in save_model(): instance = Model.objects.get(id=id)
2024-02-19 23:15:40,557 - backend.utils - ERROR - An error occurred in file D:\Documents\Coding\Python\VetCalendar\backend\backend\utils.py on line 104 in save_model(): instance.save()
2024-02-19 23:15:40,588 - backend.utils - ERROR - An error occurred in file D:\Documents\Coding\Python\VetCalendar\backend\backend\utils.py on line 96 in save_model(): instance = Model.objects.get(id=id)
2024-02-19 23:15:48,607 - backend.utils - ERROR - An error occurred in file D:\Documents\Coding\Python\VetCalendar\backend\backend\utils.py on line 104 in save_model(): instance.save()
2024-02-19 23:15:48,639 - backend.utils - ERROR - An error occurred in file D:\Documents\Coding\Python\VetCalendar\backend\backend\utils.py on line 96 in save_model(): instance = Model.objects.get(id=id)
2024-02-19 23:15:48,663 - backend.utils - ERROR - An error occurred in file D:\Documents\Coding\Python\VetCalendar\backend\backend\utils.py on line 104 in save_model(): instance.save()
