2024-02-19 23:15:48,697 - backend.utils - ERROR - An error occurred in file D:\Documents\Coding\Python\VetCalendar\backend\backend\utils.py on line 96 in save_model(): instance = Model.objects.get(id=id)
2024-02-19 23:15:48,724 - backend.utils - ERROR - An error occurred in file D:\Documents\Coding\Python\VetCalendar\backend\backend\utils.py on line 104 in save_model(): instance.save()
2024-02-19 23:15:48,755 - backend.utils - ERROR - An error occurred in file D:\Documents\Coding\Python\VetCalendar\backend\backend\utils.py on line 96 in save_model(): instance = Model.objects.get(id=id)
2024-02-19 23:16:01,245 - backend.utils - ERROR - An error occurred in file D:\Documents\Coding\Python\VetCalendar\backend\backend\utils.py on line 104 in save_model(): instance.save()
2024-02-19 23:16:01,277 - backend.utils - ERROR - An error occurred in file D:\Documents\Coding\Python\VetCalendar\backend\backend\utils.py on line 96 in save_model(): instance = Model.objects.get(id=id)
2024-02-19 23:16:01,300 - backend.utils - ERROR - An error occurred in file D:\Documents\Coding\Python\VetCalendar\backend\backend\utils.py on line 104 in save_model(): instance.save()
2024-02-19 23:16:01,333 - backend.utils - ERROR - An error occurred in file D:\Documents\Coding\Python\VetCalendar\backend\backend\utils.py on line 96 in save_model(): instance = Model.objects.get(id=id)
2024-02-19 23:16:01,357 - backend.utils - ERROR - An error occurred in file D:\Documents\Coding\Python\VetCalendar\backend\backend\utils.py on line 104 in save_model(): instance.save()
2024-02-19 23:16:01,389 - backend.utils - ERROR - An error occurred in file D:\Documents\Coding\Python\VetCalendar\backend\backend\utils.py on line 96 in save_model(): instance = Model.objects.get(id=id)
2024-02-19 23:16:44,382 - backend.utils - ERROR - An error occurred in file D:\Documents\Coding\Python\VetCalendar\backend\backend\utils.py on line 104 in save_model(): instance.save()
2024-02-19 23:16:44,414 - backend.utils - ERROR - An error occurred in file D:\Documents\Coding\Python\VetCalendar\backend\backend\utils.py on line 96 in save_model(): instance = Model.objects.get(id=id)
2024-02-19 23:16:44,439 - backend.utils - ERROR - An error occurred in file D:\Documents\Coding\Python\VetCalendar\backend\backend\utils.py on line 104 in save_model(): instance.save()
2024-02-19 23:16:44,472 - backend.utils - ERROR - An error occurred in file D:\Documents\Coding\Python\VetCalendar\backend\backend\utils.py on line 96 in save_model(): instance = Model.objects.get(id=id)
2024-02-19 23:16:44,496 - backend.utils - ERROR - An error occurred in file D:\Documents\Coding\Python\VetCalendar\backend\backend\utils.py on line 104 in save_model(): instance.save()
2024-02-19 23:16:44,527 - backend.utils - ERROR - An error occurred in file D:\Documents\Coding\Python\VetCalendar\backend\backend\utils.py on line 96 in save_model(): instance = Model.objects.get(id=id)
2024-02-19 23:18:01,111 - backend.utils - ERROR - An error occurred in file D:\Documents\Coding\Python\VetCalendar\backend\backend\utils.py on line 103 in save_model(): instance.save()
2024-02-19 23:18:01,151 - backend.utils - ERROR - An error occurred in file D:\Documents\Coding\Python\VetCalendar\backend\backend\utils.py on line 96 in save_model(): instance = Model.objects.get(id=id)
2024-02-19 23:18:01,178 - backend.utils - ERROR - An error occurred in file D:\Documents\Coding\Python\VetCalendar\backend\backend\utils.py on line 103 in save_model(): instance.save()
2024-02-19 23:18:01,210 - backend.utils - ERROR - An error occurred in file D:\Documents\Coding\Python\VetCalendar\backend\backend\utils.py on line 96 in save_model(): instance = Model.objects.get(id=id)
2024-02-19 23:18:01,234 - backend.utils - ERROR - An error occurred in file D:\Documents\Coding\Python\VetCalendar\backend\backend\utils.py on line 103 in save_model(): instance.save()
2024-02-19 23:18:01,265 - backend.utils - ERROR - An error occurred in file D:\Documents\Coding\Python\VetCalendar\backend\backend\utils.py on line 96 in save_model(): instance = Model.objects.get(id=id)
2024-02-19 23:18:54,089 - backend.utils - ERROR - An error occurred in file D:\Documents\Coding\Python\VetCalendar\backend\backend\utils.py on line 103 in save_model(): instance.save()
2024-02-19 23:18:54,129 - backend.utils - ERROR - An error occurred in file D:\Documents\Coding\Python\VetCalendar\backend\backend\utils.py on line 96 in save_model(): instance = Model.objects.get(id=id)
2024-02-19 23:18:54,155 - backend.utils - ERROR - An error occurred in file D:\Documents\Coding\Python\VetCalendar\backend\backend\utils.py on line 103 in save_model(): instance.save()
2024-02-19 23:18:54,186 - backend.utils - ERROR - An error occurred in file D:\Documents\Coding\Python\VetCalendar\backend\backend\utils.py on line 96 in save_model(): instance = Model.objects.get(id=id)
2024-02-19 23:18:54,211 - backend.utils - ERROR - An error occurred in file D:\Documents\Coding\Python\VetCalendar\backend\backend\utils.py on line 103 in save_model(): instance.save()
2024-02-19 23:22:56,275 - backend.utils - ERROR - An error occurred in file D:\Documents\Coding\Python\VetCalendar\backend\backend\utils.py on line 208 in save_form(): if not content['id'] == None:
2024-02-19 23:29:11,388 - backend.utils - ERROR - An error occurred in file D:\Documents\Coding\Python\VetCalendar\backend\backend\utils.py on line 96 in save_model(): instance = Model.objects.get(id=id)
2024-02-19 23:29:11,428 - backend.utils - ERROR - An error occurred in file D:\Documents\Coding\Python\VetCalendar\backend\backend\utils.py on line 96 in save_model(): instance = Model.objects.get(id=id)
2024-02-19 23:29:11,456 - backend.utils - ERROR - An error occurred in file D:\Documents\Coding\Python\VetCalendar\backend\backend\utils.py on line 103 in save_model(): instance.save()
2024-02-19 23:29:38,086 - backend.utils - ERROR - An error occurred in file D:\Documents\Coding\Python\VetCalendar\backend\backend\utils.py on line 103 in save_model(): instance.save()
2024-02-19 23:29:38,120 - backend.utils - ERROR - An error occurred in file D:\Documents\Coding\Python\VetCalendar\backend\backend\utils.py on line 96 in save_model(): instance = Model.objects.get(id=id)
2024-02-19 23:29:38,153 - backend.utils - ERROR - An error occurred in file D:\Documents\Coding\Python\VetCalendar\backend\backend\utils.py on line 96 in save_model(): instance = Model.objects.get(id=id)
2024-02-19 23:29:38,176 - backend.utils - ERROR - An error occurred in file D:\Documents\Coding\Python\VetCalendar\backend\backend\utils.py on line 103 in save_model(): instance.save()
2024-02-19 23:37:56,364 - backend.utils - ERROR - An error occurred in file D:\Documents\Coding\Python\VetCalendar\backend\backend\utils.py on line 160 in build_form(): form = fill_form(form, values)
2024-02-19 23:42:37,141 - backend.utils - ERROR - An error occurred in file D:\Documents\Coding\Python\VetCalendar\backend\backend\utils.py on line 103 in save_model(): instance.save()
2024-02-19 23:42:37,181 - backend.utils - ERROR - An error occurred in file D:\Documents\Coding\Python\VetCalendar\backend\backend\utils.py on line 96 in save_model(): instance = Model.objects.get(id=id)
2024-02-19 23:42:37,207 - backend.utils - ERROR - An error occurred in file D:\Documents\Coding\Python\VetCalendar\backend\backend\utils.py on line 102 in save_model(): instance = Model(**values)
2024-02-19 23:42:37,230 - backend.utils - ERROR - An error occurred in file D:\Documents\Coding\Python\VetCalendar\backend\backend\utils.py on line 96 in save_model(): instance = Model.objects.get(id=id)
2024-02-19 23:42:37,254 - backend.utils - ERROR - An error occurred in file D:\Documents\Coding\Python\VetCalendar\backend\backend\utils.py on line 102 in save_model(): instance = Model(**values)
2024-02-19 23:42:37,288 - backend.utils - ERROR - An error occurred in file D:\Documents\Coding\Python\VetCalendar\backend\backend\utils.py on line 102 in save_model(): instance = Model(**values)
2024-02-19 23:42:53,291 - backend.utils - ERROR - An error occurred in file D:\Documents\Coding\Python\VetCalendar\backend\backend\utils.py on line 103 in save_model(): instance.save()
2024-02-19 23:42:53,324 - backend.utils - ERROR - An error occurred in file D:\Documents\Coding\Python\VetCalendar\backend\backend\utils.py on line 96 in save_model(): instance = Model.objects.get(id=id)
2024-02-19 23:42:53,348 - backend.utils - ERROR - An error occurred in file D:\Documents\Coding\Python\VetCalendar\backend\backend\utils.py on line 102 in save_model(): instance = Model(**values)
2024-02-19 23:42:53,374 - backend.utils - ERROR - An error occurred in file D:\Documents\Coding\Python\VetCalendar\backend\backend\utils.py on line 96 in save_model(): instance = Model.objects.get(id=id)
2024-02-19 23:42:53,396 - backend.utils - ERROR - An error occurred in file D:\Documents\Coding\Python\VetCalendar\backend\backend\utils.py on line 102 in save_model(): instance = Model(**values)
2024-02-19 23:42:53,426 - backend.utils - ERROR - An error occurred in file D:\Documents\Coding\Python\VetCalendar\backend\backend\utils.py on line 102 in save_model(): instance = Model(**values)
2024-02-19 23:45:00,130 - backend.utils - ERROR - An error occurred in file D:\Documents\Coding\Python\VetCalendar\backend\backend\utils.py on line 103 in save_model(): instance.save()
2024-02-19 23:45:00,171 - backend.utils - ERROR - An error occurred in file D:\Documents\Coding\Python\VetCalendar\backend\backend\utils.py on line 96 in save_model(): instance = Model.objects.get(id=id)
2024-02-19 23:45:00,204 - backend.utils - ERROR - An error occurred in file D:\Documents\Coding\Python\VetCalendar\backend\backend\utils.py on line 102 in save_model(): instance = Model(**values)
2024-02-19 23:45:00,229 - backend.utils - ERROR - An error occurred in file D:\Documents\Coding\Python\VetCalendar\backend\backend\utils.py on line 96 in save_model(): instance = Model.objects.get(id=id)
2024-02-19 23:45:00,253 - backend.utils - ERROR - An error occurred in file D:\Documents\Coding\Python\VetCalendar\backend\backend\utils.py on line 102 in save_model(): instance = Model(**values)
2024-02-19 23:45:00,278 - backend.utils - ERROR - An error occurred in file D:\Documents\Coding\Python\VetCalendar\backend\backend\utils.py on line 98 in save_model(): setattr(instance, key, value)
2024-02-19 23:45:00,300 - backend.utils - ERROR - An error occurred in file D:\Documents\Coding\Python\VetCalendar\backend\backend\utils.py on line 102 in save_model(): instance = Model(**values)
2024-02-19 23:53:22,778 - backend.utils - ERROR - An error occurred in file D:\Documents\Coding\Python\VetCalendar\backend\backend\utils.py on line 103 in save_model(): if is_foreign_key(Model, key):
2024-02-19 23:53:22,813 - backend.utils - ERROR - An error occurred in file D:\Documents\Coding\Python\VetCalendar\backend\backend\utils.py on line 113 in save_model(): instance.save()
2024-02-19 23:53:22,845 - backend.utils - ERROR - An error occurred in file D:\Documents\Coding\Python\VetCalendar\backend\backend\utils.py on line 101 in save_model(): instance = Model.objects.get(id=id)
2024-02-19 23:53:22,869 - backend.utils - ERROR - An error occurred in file D:\Documents\Coding\Python\VetCalendar\backend\backend\utils.py on line 112 in save_model(): instance = Model(**values)
2024-02-19 23:53:22,893 - backend.utils - ERROR - An error occurred in file D:\Documents\Coding\Python\VetCalendar\backend\backend\utils.py on line 101 in save_model(): instance = Model.objects.get(id=id)
2024-02-19 23:53:22,917 - backend.utils - ERROR - An error occurred in file D:\Documents\Coding\Python\VetCalendar\backend\backend\utils.py on line 112 in save_model(): instance = Model(**values)
2024-02-19 23:53:22,943 - backend.utils - ERROR - An error occurred in file D:\Documents\Coding\Python\VetCalendar\backend\backend\utils.py on line 103 in save_model(): if is_foreign_key(Model, key):
2024-02-19 23:53:22,964 - backend.utils - ERROR - An error occurred in file D:\Documents\Coding\Python\VetCalendar\backend\backend\utils.py on line 112 in save_model(): instance = Model(**values)
2024-02-19 23:53:32,334 - backend.utils - ERROR - An error occurred in file D:\Documents\Coding\Python\VetCalendar\backend\backend\utils.py on line 103 in save_model(): if is_foreign_key(Model, key):
2024-02-19 23:53:32,358 - backend.utils - ERROR - An error occurred in file D:\Documents\Coding\Python\VetCalendar\backend\backend\utils.py on line 113 in save_model(): instance.save()
2024-02-19 23:53:32,389 - backend.utils - ERROR - An error occurred in file D:\Documents\Coding\Python\VetCalendar\backend\backend\utils.py on line 101 in save_model(): instance = Model.objects.get(id=id)
2024-02-19 23:53:32,414 - backend.utils - ERROR - An error occurred in file D:\Documents\Coding\Python\VetCalendar\backend\backend\utils.py on line 112 in save_model(): instance = Model(**values)
2024-02-19 23:53:32,439 - backend.utils - ERROR - An error occurred in file D:\Documents\Coding\Python\VetCalendar\backend\backend\utils.py on line 101 in save_model(): instance = Model.objects.get(id=id)
2024-02-19 23:53:32,463 - backend.utils - ERROR - An error occurred in file D:\Documents\Coding\Python\VetCalendar\backend\backend\utils.py on line 112 in save_model(): instance = Model(**values)
2024-02-19 23:53:32,490 - backend.utils - ERROR - An error occurred in file D:\Documents\Coding\Python\VetCalendar\backend\backend\utils.py on line 103 in save_model(): if is_foreign_key(Model, key):
2024-02-19 23:53:32,513 - backend.utils - ERROR - An error occurred in file D:\Documents\Coding\Python\VetCalendar\backend\backend\utils.py on line 112 in save_model(): instance = Model(**values)
2024-02-19 23:55:18,741 - backend.utils - ERROR - An error occurred in file D:\Documents\Coding\Python\VetCalendar\backend\backend\utils.py on line 113 in save_model(): instance.save()
2024-02-19 23:55:18,780 - backend.utils - ERROR - An error occurred in file D:\Documents\Coding\Python\VetCalendar\backend\backend\utils.py on line 101 in save_model(): instance = Model.objects.get(id=id)
2024-02-19 23:55:18,803 - backend.utils - ERROR - An error occurred in file D:\Documents\Coding\Python\VetCalendar\backend\backend\utils.py on line 112 in save_model(): instance = Model(**values)
2024-02-19 23:55:18,828 - backend.utils - ERROR - An error occurred in file D:\Documents\Coding\Python\VetCalendar\backend\backend\utils.py on line 101 in save_model(): instance = Model.objects.get(id=id)
2024-02-19 23:55:18,854 - backend.utils - ERROR - An error occurred in file D:\Documents\Coding\Python\VetCalendar\backend\backend\utils.py on line 112 in save_model(): instance = Model(**values)
2024-02-19 23:55:18,880 - backend.utils - ERROR - An error occurred in file D:\Documents\Coding\Python\VetCalendar\backend\backend\utils.py on line 106 in save_model(): setattr(instance, key, foreign_instance)
2024-02-19 23:55:18,905 - backend.utils - ERROR - An error occurred in file D:\Documents\Coding\Python\VetCalendar\backend\backend\utils.py on line 112 in save_model(): instance = Model(**values)
2024-02-20 00:02:15,133 - backend.utils - ERROR - An error occurred in file D:\Documents\Coding\Python\VetCalendar\backend\backend\utils.py on line 112 in save_model(): instance.save()
2024-02-20 00:02:15,170 - backend.utils - ERROR - An error occurred in file D:\Documents\Coding\Python\VetCalendar\backend\backend\utils.py on line 103 in save_model(): value = get_model_instance(model['app'], key.capitalize(), value)
2024-02-20 00:02:15,200 - backend.utils - ERROR - An error occurred in file D:\Documents\Coding\Python\VetCalendar\backend\backend\utils.py on line 103 in save_model(): value = get_model_instance(model['app'], key.capitalize(), value)
2024-02-20 00:02:15,233 - backend.utils - ERROR - An error occurred in file D:\Documents\Coding\Python\VetCalendar\backend\backend\utils.py on line 103 in save_model(): value = get_model_instance(model['app'], key.capitalize(), value)
2024-02-20 00:02:15,263 - backend.utils - ERROR - An error occurred in file D:\Documents\Coding\Python\VetCalendar\backend\backend\utils.py on line 103 in save_model(): value = get_model_instance(model['app'], key.capitalize(), value)
2024-02-20 00:02:15,294 - backend.utils - ERROR - An error occurred in file D:\Documents\Coding\Python\VetCalendar\backend\backend\utils.py on line 107 in save_model(): setattr(instance, key, value)
2024-02-20 00:02:15,318 - backend.utils - ERROR - An error occurred in file D:\Documents\Coding\Python\VetCalendar\backend\backend\utils.py on line 111 in save_model(): instance = Model(**values)
2024-02-20 00:02:22,378 - backend.utils - ERROR - An error occurred in file D:\Documents\Coding\Python\VetCalendar\backend\backend\utils.py on line 112 in save_model(): instance.save()
2024-02-20 00:02:22,412 - backend.utils - ERROR - An error occurred in file D:\Documents\Coding\Python\VetCalendar\backend\backend\utils.py on line 103 in save_model(): value = get_model_instance(model['app'], key.capitalize(), value)
2024-02-20 00:02:22,444 - backend.utils - ERROR - An error occurred in file D:\Documents\Coding\Python\VetCalendar\backend\backend\utils.py on line 103 in save_model(): value = get_model_instance(model['app'], key.capitalize(), value)
2024-02-20 00:02:22,474 - backend.utils - ERROR - An error occurred in file D:\Documents\Coding\Python\VetCalendar\backend\backend\utils.py on line 103 in save_model(): value = get_model_instance(model['app'], key.capitalize(), value)
2024-02-20 00:02:22,506 - backend.utils - ERROR - An error occurred in file D:\Documents\Coding\Python\VetCalendar\backend\backend\utils.py on line 103 in save_model(): value = get_model_instance(model['app'], key.capitalize(), value)
2024-02-20 00:02:22,536 - backend.utils - ERROR - An error occurred in file D:\Documents\Coding\Python\VetCalendar\backend\backend\utils.py on line 107 in save_model(): setattr(instance, key, value)
2024-02-20 00:02:22,560 - backend.utils - ERROR - An error occurred in file D:\Documents\Coding\Python\VetCalendar\backend\backend\utils.py on line 111 in save_model(): instance = Model(**values)
2024-02-20 00:05:58,474 - backend.utils - ERROR - An error occurred in file D:\Documents\Coding\Python\VetCalendar\backend\backend\utils.py on line 219 in save_form(): save_model(form['model'], form_values , form['id'])
2024-02-20 00:06:10,913 - backend.utils - ERROR - An error occurred in file D:\Documents\Coding\Python\VetCalendar\backend\backend\utils.py on line 220 in save_form(): save_model(form['model'], form_values, None)
2024-02-20 00:09:23,625 - backend.utils - ERROR - An error occurred in file D:\Documents\Coding\Python\VetCalendar\backend\backend\utils.py on line 219 in save_form(): save_model(form['model'], form_values , form['id'])
2024-02-20 00:12:29,272 - backend.utils - ERROR - An error occurred in file D:\Documents\Coding\Python\VetCalendar\backend\backend\utils.py on line 220 in save_form(): save_model(form['model'], form_values , form['id'])
2024-02-20 00:14:46,165 - backend.utils - ERROR - An error occurred in file D:\Documents\Coding\Python\VetCalendar\backend\backend\utils.py on line 220 in save_form(): save_model(form['model'], form_values , form['id'])
2024-02-20 00:17:03,048 - backend.utils - ERROR - An error occurred in file D:\Documents\Coding\Python\VetCalendar\backend\backend\utils.py on line 221 in save_form(): save_model(form['model'], form_values , form['id'])
2024-02-20 00:18:45,943 - backend.utils - ERROR - An error occurred in file D:\Documents\Coding\Python\VetCalendar\backend\backend\utils.py on line 222 in save_form(): save_model(form['model'], form_values , form['id'])
